2025-08-28 23:44:18 [INFO] dfmea_app: [VectorStoreAgent] ðŸŽ¯ Upload complete: 3141 vectors stored in dfmea_collection
2025-08-28 23:44:18 [INFO] dfmea_app: [VectorStore] âœ… Inserted 3141 vectors into Qdrant
INFO:     127.0.0.1:49229 - "POST /dfmea/generate HTTP/1.1" 500 Internal Server Error
ERROR:    Exception in ASGI application
Traceback (most recent call last):
  File "C:\Users\AS9969\Desktop\Ashish Work Folder\dfmea_fina_env\Lib\site-packages\fastapi\encoders.py", line 324, in jsonable_encoder
    data = dict(obj)
           ^^^^^^^^^
TypeError: 'coroutine' object is not iterable

During handling of the above exception, another exception occurred:

Traceback (most recent call last):
  File "C:\Users\AS9969\Desktop\Ashish Work Folder\dfmea_fina_env\Lib\site-packages\fastapi\encoders.py", line 329, in jsonable_encoder
    data = vars(obj)
           ^^^^^^^^^
TypeError: vars() argument must have __dict__ attribute

The above exception was the direct cause of the following exception:

Traceback (most recent call last):
  File "C:\Users\AS9969\Desktop\Ashish Work Folder\dfmea_fina_env\Lib\site-packages\uvicorn\protocols\http\httptools_impl.py", line 409, in run_asgi
    result = await app(  # type: ignore[func-returns-value]
             ^^^^^^^^^^^^^^^^^^^^^^^^^^^^^^^^^^^^^^^^^^^^^^
  File "C:\Users\AS9969\Desktop\Ashish Work Folder\dfmea_fina_env\Lib\site-packages\uvicorn\middleware\proxy_headers.py", line 60, in __call__
    return await self.app(scope, receive, send)
           ^^^^^^^^^^^^^^^^^^^^^^^^^^^^^^^^^^^^
  File "C:\Users\AS9969\Desktop\Ashish Work Folder\dfmea_fina_env\Lib\site-packages\fastapi\applications.py", line 1054, in __call__
    await super().__call__(scope, receive, send)
  File "C:\Users\AS9969\Desktop\Ashish Work Folder\dfmea_fina_env\Lib\site-packages\starlette\applications.py", line 112, in __call__
    await self.middleware_stack(scope, receive, send)
  File "C:\Users\AS9969\Desktop\Ashish Work Folder\dfmea_fina_env\Lib\site-packages\starlette\middleware\errors.py", line 187, in __call__
    raise exc
  File "C:\Users\AS9969\Desktop\Ashish Work Folder\dfmea_fina_env\Lib\site-packages\starlette\middleware\errors.py", line 165, in __call__
    await self.app(scope, receive, _send)
  File "C:\Users\AS9969\Desktop\Ashish Work Folder\dfmea_fina_env\Lib\site-packages\starlette\middleware\cors.py", line 85, in __call__
    await self.app(scope, receive, send)
  File "C:\Users\AS9969\Desktop\Ashish Work Folder\dfmea_fina_env\Lib\site-packages\starlette\middleware\exceptions.py", line 62, in __call__
    await wrap_app_handling_exceptions(self.app, conn)(scope, receive, send)
  File "C:\Users\AS9969\Desktop\Ashish Work Folder\dfmea_fina_env\Lib\site-packages\starlette\_exception_handler.py", line 53, in wrapped_app
    raise exc
  File "C:\Users\AS9969\Desktop\Ashish Work Folder\dfmea_fina_env\Lib\site-packages\starlette\_exception_handler.py", line 42, in wrapped_app
    await app(scope, receive, sender)
  File "C:\Users\AS9969\Desktop\Ashish Work Folder\dfmea_fina_env\Lib\site-packages\starlette\routing.py", line 714, in __call__    
    await self.middleware_stack(scope, receive, send)
  File "C:\Users\AS9969\Desktop\Ashish Work Folder\dfmea_fina_env\Lib\site-packages\starlette\routing.py", line 734, in app
    await route.handle(scope, receive, send)
  File "C:\Users\AS9969\Desktop\Ashish Work Folder\dfmea_fina_env\Lib\site-packages\starlette\routing.py", line 288, in handle      
    await self.app(scope, receive, send)
  File "C:\Users\AS9969\Desktop\Ashish Work Folder\dfmea_fina_env\Lib\site-packages\starlette\routing.py", line 76, in app
    await wrap_app_handling_exceptions(app, request)(scope, receive, send)
  File "C:\Users\AS9969\Desktop\Ashish Work Folder\dfmea_fina_env\Lib\site-packages\starlette\_exception_handler.py", line 53, in wrapped_app
    raise exc
  File "C:\Users\AS9969\Desktop\Ashish Work Folder\dfmea_fina_env\Lib\site-packages\starlette\_exception_handler.py", line 42, in wrapped_app
    await app(scope, receive, sender)
  File "C:\Users\AS9969\Desktop\Ashish Work Folder\dfmea_fina_env\Lib\site-packages\starlette\routing.py", line 73, in app
    response = await f(request)
               ^^^^^^^^^^^^^^^^
  File "C:\Users\AS9969\Desktop\Ashish Work Folder\dfmea_fina_env\Lib\site-packages\fastapi\routing.py", line 327, in app
    content = await serialize_response(
              ^^^^^^^^^^^^^^^^^^^^^^^^^
  File "C:\Users\AS9969\Desktop\Ashish Work Folder\dfmea_fina_env\Lib\site-packages\fastapi\routing.py", line 201, in serialize_response
    return jsonable_encoder(response_content)
           ^^^^^^^^^^^^^^^^^^^^^^^^^^^^^^^^^^
  File "C:\Users\AS9969\Desktop\Ashish Work Folder\dfmea_fina_env\Lib\site-packages\fastapi\encoders.py", line 289, in jsonable_encoder
    encoded_value = jsonable_encoder(
                    ^^^^^^^^^^^^^^^^^
  File "C:\Users\AS9969\Desktop\Ashish Work Folder\dfmea_fina_env\Lib\site-packages\fastapi\encoders.py", line 332, in jsonable_encoder
    raise ValueError(errors) from e
ValueError: [TypeError("'coroutine' object is not iterable"), TypeError('vars() argument must have __dict__ attribute')]
